WARNING:django.request:Not Found: /
WARNING:django.request:Not Found: /accounts/profile/
WARNING:django.request:Not Found: /
INFO:django.utils.autoreload:/home/atala/Personal/alx-backend-python/Django-Middleware-0x03/chats/middleware.py changed, reloading.
INFO:django.utils.autoreload:/home/atala/Personal/alx-backend-python/Django-Middleware-0x03/chats/middleware.py changed, reloading.
INFO:django.utils.autoreload:/home/atala/Personal/alx-backend-python/Django-Middleware-0x03/chats/middleware.py changed, reloading.
WARNING:django.request:Not Found: /
INFO:django.utils.autoreload:/home/atala/Personal/alx-backend-python/Django-Middleware-0x03/chats/middleware.py changed, reloading.
INFO:django.utils.autoreload:/home/atala/Personal/alx-backend-python/Django-Middleware-0x03/chats/middleware.py changed, reloading.
INFO:django.utils.autoreload:/home/atala/Personal/alx-backend-python/Django-Middleware-0x03/chats/middleware.py changed, reloading.
INFO:root:2025-07-08 11:04:18.226741 - User: johndoe - Path: /
WARNING:django.request:Not Found: /
INFO:root:2025-07-08 12:22:43.786478 - User: johndoe - Path: /
ERROR:django.request:Internal Server Error: /
Traceback (most recent call last):
  File "/home/atala/Personal/alx-backend-python/messaging_app/venv/lib/python3.10/site-packages/django/core/handlers/exception.py", line 55, in inner
    response = get_response(request)
TypeError: 'PermissionDenied' object is not callable
INFO:django.utils.autoreload:/home/atala/Personal/alx-backend-python/Django-Middleware-0x03/chats/middleware.py changed, reloading.
INFO:root:2025-07-08 12:22:58.027567 - User: johndoe - Path: /
ERROR:django.request:Internal Server Error: /
Traceback (most recent call last):
  File "/home/atala/Personal/alx-backend-python/messaging_app/venv/lib/python3.10/site-packages/django/core/handlers/exception.py", line 55, in inner
    response = get_response(request)
TypeError: 'PermissionDenied' object is not callable
INFO:django.utils.autoreload:/home/atala/Personal/alx-backend-python/Django-Middleware-0x03/chats/middleware.py changed, reloading.
INFO:root:2025-07-08 12:23:49.945837 - User: johndoe - Path: /
ERROR:django.request:Internal Server Error: /
Traceback (most recent call last):
  File "/home/atala/Personal/alx-backend-python/messaging_app/venv/lib/python3.10/site-packages/django/core/handlers/exception.py", line 55, in inner
    response = get_response(request)
TypeError: 'PermissionDenied' object is not callable
INFO:django.utils.autoreload:/home/atala/Personal/alx-backend-python/Django-Middleware-0x03/chats/middleware.py changed, reloading.
INFO:root:2025-07-08 12:26:20.871139 - User: johndoe - Path: /
ERROR:django.request:Internal Server Error: /
Traceback (most recent call last):
  File "/home/atala/Personal/alx-backend-python/messaging_app/venv/lib/python3.10/site-packages/django/core/handlers/exception.py", line 55, in inner
    response = get_response(request)
TypeError: 'PermissionDenied' object is not callable
INFO:root:2025-07-08 12:29:26.124528 - User: johndoe - Path: /
ERROR:django.request:Internal Server Error: /
Traceback (most recent call last):
  File "/home/atala/Personal/alx-backend-python/messaging_app/venv/lib/python3.10/site-packages/django/core/handlers/exception.py", line 55, in inner
    response = get_response(request)
TypeError: 'PermissionDenied' object is not callable
INFO:root:2025-07-08 12:36:19.097876 - User: johndoe - Path: /
ERROR:django.request:Internal Server Error: /
Traceback (most recent call last):
  File "/home/atala/Personal/alx-backend-python/messaging_app/venv/lib/python3.10/site-packages/django/core/handlers/exception.py", line 55, in inner
    response = get_response(request)
TypeError: 'PermissionDenied' object is not callable
INFO:root:2025-07-08 12:47:12.015553 - User: johndoe - Path: /
ERROR:django.request:Internal Server Error: /
Traceback (most recent call last):
  File "/home/atala/Personal/alx-backend-python/messaging_app/venv/lib/python3.10/site-packages/django/core/handlers/exception.py", line 55, in inner
    response = get_response(request)
TypeError: 'PermissionDenied' object is not callable
INFO:root:2025-07-28 05:34:48.511187 - User: AnonymousUser - Path: /
ERROR:django.request:Internal Server Error: /
Traceback (most recent call last):
  File "/home/atala/Personal/alx-backend-python/messaging_app/venv/lib/python3.10/site-packages/django/core/handlers/exception.py", line 55, in inner
    response = get_response(request)
TypeError: 'PermissionDenied' object is not callable
INFO:root:2025-07-28 05:34:49.023821 - User: AnonymousUser - Path: /favicon.ico
ERROR:django.request:Internal Server Error: /favicon.ico
Traceback (most recent call last):
  File "/home/atala/Personal/alx-backend-python/messaging_app/venv/lib/python3.10/site-packages/django/core/handlers/exception.py", line 55, in inner
    response = get_response(request)
TypeError: 'PermissionDenied' object is not callable
INFO:django.utils.autoreload:/home/atala/Personal/alx-backend-python/Django-Middleware-0x03/chats/middleware.py changed, reloading.
INFO:django.utils.autoreload:/home/atala/Personal/alx-backend-python/Django-Middleware-0x03/chats/middleware.py changed, reloading.
INFO:root:2025-07-28 05:37:33.290710 - User: AnonymousUser - Path: /
ERROR:django.request:Internal Server Error: /
Traceback (most recent call last):
  File "/home/atala/Personal/alx-backend-python/messaging_app/venv/lib/python3.10/site-packages/django/core/handlers/exception.py", line 55, in inner
    response = get_response(request)
TypeError: 'PermissionDenied' object is not callable
INFO:root:2025-07-28 05:37:33.557091 - User: AnonymousUser - Path: /favicon.ico
ERROR:django.request:Internal Server Error: /favicon.ico
Traceback (most recent call last):
  File "/home/atala/Personal/alx-backend-python/messaging_app/venv/lib/python3.10/site-packages/django/core/handlers/exception.py", line 55, in inner
    response = get_response(request)
TypeError: 'PermissionDenied' object is not callable
INFO:django.utils.autoreload:/home/atala/Personal/alx-backend-python/Django-Middleware-0x03/chats/middleware.py changed, reloading.
INFO:django.utils.autoreload:/home/atala/Personal/alx-backend-python/Django-Middleware-0x03/chats/middleware.py changed, reloading.
INFO:django.utils.autoreload:/home/atala/Personal/alx-backend-python/Django-Middleware-0x03/messaging_app/settings.py changed, reloading.
INFO:django.utils.autoreload:/home/atala/Personal/alx-backend-python/Django-Middleware-0x03/messaging_app/settings.py changed, reloading.
INFO:root:2025-07-28 05:40:52.374952 - User: AnonymousUser - Path: /
WARNING:django.request:Forbidden (Permission denied): /
Traceback (most recent call last):
  File "/home/atala/Personal/alx-backend-python/messaging_app/venv/lib/python3.10/site-packages/django/core/handlers/exception.py", line 55, in inner
    response = get_response(request)
  File "/home/atala/Personal/alx-backend-python/Django-Middleware-0x03/chats/middleware.py", line 47, in __call__
    raise PermissionDenied("Access is only allowed between 9 AM and 6 PM.")
django.core.exceptions.PermissionDenied: Access is only allowed between 9 AM and 6 PM.
INFO:root:2025-07-28 05:40:52.567775 - User: AnonymousUser - Path: /favicon.ico
WARNING:django.request:Forbidden (Permission denied): /favicon.ico
Traceback (most recent call last):
  File "/home/atala/Personal/alx-backend-python/messaging_app/venv/lib/python3.10/site-packages/django/core/handlers/exception.py", line 55, in inner
    response = get_response(request)
  File "/home/atala/Personal/alx-backend-python/Django-Middleware-0x03/chats/middleware.py", line 47, in __call__
    raise PermissionDenied("Access is only allowed between 9 AM and 6 PM.")
django.core.exceptions.PermissionDenied: Access is only allowed between 9 AM and 6 PM.
INFO:root:2025-07-28 06:30:28.517552 - User: AnonymousUser - Path: /
WARNING:django.request:Forbidden (Permission denied): /
Traceback (most recent call last):
  File "/home/atala/Personal/alx-backend-python/messaging_app/venv/lib/python3.10/site-packages/django/core/handlers/exception.py", line 55, in inner
    response = get_response(request)
  File "/home/atala/Personal/alx-backend-python/Django-Middleware-0x03/chats/middleware.py", line 47, in __call__
    raise PermissionDenied("Access is only allowed between 9 AM and 6 PM.")
django.core.exceptions.PermissionDenied: Access is only allowed between 9 AM and 6 PM.
INFO:root:2025-07-28 06:30:28.574858 - User: AnonymousUser - Path: /favicon.ico
WARNING:django.request:Forbidden (Permission denied): /favicon.ico
Traceback (most recent call last):
  File "/home/atala/Personal/alx-backend-python/messaging_app/venv/lib/python3.10/site-packages/django/core/handlers/exception.py", line 55, in inner
    response = get_response(request)
  File "/home/atala/Personal/alx-backend-python/Django-Middleware-0x03/chats/middleware.py", line 47, in __call__
    raise PermissionDenied("Access is only allowed between 9 AM and 6 PM.")
django.core.exceptions.PermissionDenied: Access is only allowed between 9 AM and 6 PM.
INFO:root:2025-07-28 06:30:29.443916 - User: AnonymousUser - Path: /
WARNING:django.request:Forbidden (Permission denied): /
Traceback (most recent call last):
  File "/home/atala/Personal/alx-backend-python/messaging_app/venv/lib/python3.10/site-packages/django/core/handlers/exception.py", line 55, in inner
    response = get_response(request)
  File "/home/atala/Personal/alx-backend-python/Django-Middleware-0x03/chats/middleware.py", line 47, in __call__
    raise PermissionDenied("Access is only allowed between 9 AM and 6 PM.")
django.core.exceptions.PermissionDenied: Access is only allowed between 9 AM and 6 PM.
INFO:root:2025-07-28 06:30:29.492002 - User: AnonymousUser - Path: /favicon.ico
WARNING:django.request:Forbidden (Permission denied): /favicon.ico
Traceback (most recent call last):
  File "/home/atala/Personal/alx-backend-python/messaging_app/venv/lib/python3.10/site-packages/django/core/handlers/exception.py", line 55, in inner
    response = get_response(request)
  File "/home/atala/Personal/alx-backend-python/Django-Middleware-0x03/chats/middleware.py", line 47, in __call__
    raise PermissionDenied("Access is only allowed between 9 AM and 6 PM.")
django.core.exceptions.PermissionDenied: Access is only allowed between 9 AM and 6 PM.
INFO:root:2025-07-28 06:30:30.141522 - User: AnonymousUser - Path: /
WARNING:django.request:Forbidden (Permission denied): /
Traceback (most recent call last):
  File "/home/atala/Personal/alx-backend-python/messaging_app/venv/lib/python3.10/site-packages/django/core/handlers/exception.py", line 55, in inner
    response = get_response(request)
  File "/home/atala/Personal/alx-backend-python/Django-Middleware-0x03/chats/middleware.py", line 47, in __call__
    raise PermissionDenied("Access is only allowed between 9 AM and 6 PM.")
django.core.exceptions.PermissionDenied: Access is only allowed between 9 AM and 6 PM.
INFO:root:2025-07-28 06:30:30.202360 - User: AnonymousUser - Path: /favicon.ico
WARNING:django.request:Forbidden (Permission denied): /favicon.ico
Traceback (most recent call last):
  File "/home/atala/Personal/alx-backend-python/messaging_app/venv/lib/python3.10/site-packages/django/core/handlers/exception.py", line 55, in inner
    response = get_response(request)
  File "/home/atala/Personal/alx-backend-python/Django-Middleware-0x03/chats/middleware.py", line 47, in __call__
    raise PermissionDenied("Access is only allowed between 9 AM and 6 PM.")
django.core.exceptions.PermissionDenied: Access is only allowed between 9 AM and 6 PM.
INFO:root:2025-07-28 06:30:30.689970 - User: AnonymousUser - Path: /
WARNING:django.request:Forbidden (Permission denied): /
Traceback (most recent call last):
  File "/home/atala/Personal/alx-backend-python/messaging_app/venv/lib/python3.10/site-packages/django/core/handlers/exception.py", line 55, in inner
    response = get_response(request)
  File "/home/atala/Personal/alx-backend-python/Django-Middleware-0x03/chats/middleware.py", line 47, in __call__
    raise PermissionDenied("Access is only allowed between 9 AM and 6 PM.")
django.core.exceptions.PermissionDenied: Access is only allowed between 9 AM and 6 PM.
INFO:root:2025-07-28 06:30:30.735915 - User: AnonymousUser - Path: /favicon.ico
WARNING:django.request:Forbidden (Permission denied): /favicon.ico
Traceback (most recent call last):
  File "/home/atala/Personal/alx-backend-python/messaging_app/venv/lib/python3.10/site-packages/django/core/handlers/exception.py", line 55, in inner
    response = get_response(request)
  File "/home/atala/Personal/alx-backend-python/Django-Middleware-0x03/chats/middleware.py", line 47, in __call__
    raise PermissionDenied("Access is only allowed between 9 AM and 6 PM.")
django.core.exceptions.PermissionDenied: Access is only allowed between 9 AM and 6 PM.
INFO:django.utils.autoreload:/home/atala/Personal/alx-backend-python/Django-Middleware-0x03/chats/middleware.py changed, reloading.
INFO:django.utils.autoreload:/home/atala/Personal/alx-backend-python/Django-Middleware-0x03/chats/middleware.py changed, reloading.
INFO:django.utils.autoreload:/home/atala/Personal/alx-backend-python/Django-Middleware-0x03/chats/middleware.py changed, reloading.
INFO:root:2025-07-28 06:31:02.905839 - User: AnonymousUser - Path: /
WARNING:django.request:Forbidden (Permission denied): /
Traceback (most recent call last):
  File "/home/atala/Personal/alx-backend-python/messaging_app/venv/lib/python3.10/site-packages/django/core/handlers/exception.py", line 55, in inner
    response = get_response(request)
  File "/home/atala/Personal/alx-backend-python/Django-Middleware-0x03/chats/middleware.py", line 48, in __call__
    raise PermissionDenied("Access is only allowed between 9 AM and 6 PM.")
django.core.exceptions.PermissionDenied: Access is only allowed between 9 AM and 6 PM.
INFO:root:2025-07-28 06:31:02.987176 - User: AnonymousUser - Path: /favicon.ico
WARNING:django.request:Forbidden (Permission denied): /favicon.ico
Traceback (most recent call last):
  File "/home/atala/Personal/alx-backend-python/messaging_app/venv/lib/python3.10/site-packages/django/core/handlers/exception.py", line 55, in inner
    response = get_response(request)
  File "/home/atala/Personal/alx-backend-python/Django-Middleware-0x03/chats/middleware.py", line 48, in __call__
    raise PermissionDenied("Access is only allowed between 9 AM and 6 PM.")
django.core.exceptions.PermissionDenied: Access is only allowed between 9 AM and 6 PM.
INFO:root:2025-07-28 06:31:42.677011 - User: AnonymousUser - Path: /
WARNING:django.request:Forbidden (Permission denied): /
Traceback (most recent call last):
  File "/home/atala/Personal/alx-backend-python/messaging_app/venv/lib/python3.10/site-packages/django/core/handlers/exception.py", line 55, in inner
    response = get_response(request)
  File "/home/atala/Personal/alx-backend-python/Django-Middleware-0x03/chats/middleware.py", line 48, in __call__
    raise PermissionDenied("Access is only allowed between 9 AM and 6 PM.")
django.core.exceptions.PermissionDenied: Access is only allowed between 9 AM and 6 PM.
INFO:root:2025-07-28 06:31:42.730851 - User: AnonymousUser - Path: /favicon.ico
WARNING:django.request:Forbidden (Permission denied): /favicon.ico
Traceback (most recent call last):
  File "/home/atala/Personal/alx-backend-python/messaging_app/venv/lib/python3.10/site-packages/django/core/handlers/exception.py", line 55, in inner
    response = get_response(request)
  File "/home/atala/Personal/alx-backend-python/Django-Middleware-0x03/chats/middleware.py", line 48, in __call__
    raise PermissionDenied("Access is only allowed between 9 AM and 6 PM.")
django.core.exceptions.PermissionDenied: Access is only allowed between 9 AM and 6 PM.
INFO:root:2025-07-28 06:31:45.842387 - User: AnonymousUser - Path: /
WARNING:django.request:Forbidden (Permission denied): /
Traceback (most recent call last):
  File "/home/atala/Personal/alx-backend-python/messaging_app/venv/lib/python3.10/site-packages/django/core/handlers/exception.py", line 55, in inner
    response = get_response(request)
  File "/home/atala/Personal/alx-backend-python/Django-Middleware-0x03/chats/middleware.py", line 48, in __call__
    raise PermissionDenied("Access is only allowed between 9 AM and 6 PM.")
django.core.exceptions.PermissionDenied: Access is only allowed between 9 AM and 6 PM.
INFO:root:2025-07-28 06:31:45.902161 - User: AnonymousUser - Path: /favicon.ico
WARNING:django.request:Forbidden (Permission denied): /favicon.ico
Traceback (most recent call last):
  File "/home/atala/Personal/alx-backend-python/messaging_app/venv/lib/python3.10/site-packages/django/core/handlers/exception.py", line 55, in inner
    response = get_response(request)
  File "/home/atala/Personal/alx-backend-python/Django-Middleware-0x03/chats/middleware.py", line 48, in __call__
    raise PermissionDenied("Access is only allowed between 9 AM and 6 PM.")
django.core.exceptions.PermissionDenied: Access is only allowed between 9 AM and 6 PM.
INFO:root:2025-07-28 06:31:56.821039 - User: AnonymousUser - Path: /
WARNING:django.request:Forbidden (Permission denied): /
Traceback (most recent call last):
  File "/home/atala/Personal/alx-backend-python/messaging_app/venv/lib/python3.10/site-packages/django/core/handlers/exception.py", line 55, in inner
    response = get_response(request)
  File "/home/atala/Personal/alx-backend-python/Django-Middleware-0x03/chats/middleware.py", line 48, in __call__
    raise PermissionDenied("Access is only allowed between 9 AM and 6 PM.")
django.core.exceptions.PermissionDenied: Access is only allowed between 9 AM and 6 PM.
INFO:root:2025-07-28 06:31:56.875474 - User: AnonymousUser - Path: /favicon.ico
WARNING:django.request:Forbidden (Permission denied): /favicon.ico
Traceback (most recent call last):
  File "/home/atala/Personal/alx-backend-python/messaging_app/venv/lib/python3.10/site-packages/django/core/handlers/exception.py", line 55, in inner
    response = get_response(request)
  File "/home/atala/Personal/alx-backend-python/Django-Middleware-0x03/chats/middleware.py", line 48, in __call__
    raise PermissionDenied("Access is only allowed between 9 AM and 6 PM.")
django.core.exceptions.PermissionDenied: Access is only allowed between 9 AM and 6 PM.
INFO:root:2025-07-28 06:32:35.317414 - User: AnonymousUser - Path: /
WARNING:django.request:Forbidden (Permission denied): /
Traceback (most recent call last):
  File "/home/atala/Personal/alx-backend-python/messaging_app/venv/lib/python3.10/site-packages/django/core/handlers/exception.py", line 55, in inner
    response = get_response(request)
  File "/home/atala/Personal/alx-backend-python/Django-Middleware-0x03/chats/middleware.py", line 48, in __call__
    raise PermissionDenied("Access is only allowed between 9 AM and 6 PM.")
django.core.exceptions.PermissionDenied: Access is only allowed between 9 AM and 6 PM.
INFO:root:2025-07-28 06:32:35.375805 - User: AnonymousUser - Path: /favicon.ico
WARNING:django.request:Forbidden (Permission denied): /favicon.ico
Traceback (most recent call last):
  File "/home/atala/Personal/alx-backend-python/messaging_app/venv/lib/python3.10/site-packages/django/core/handlers/exception.py", line 55, in inner
    response = get_response(request)
  File "/home/atala/Personal/alx-backend-python/Django-Middleware-0x03/chats/middleware.py", line 48, in __call__
    raise PermissionDenied("Access is only allowed between 9 AM and 6 PM.")
django.core.exceptions.PermissionDenied: Access is only allowed between 9 AM and 6 PM.
INFO:root:2025-07-28 06:33:04.076809 - User: AnonymousUser - Path: /
WARNING:django.request:Forbidden (Permission denied): /
Traceback (most recent call last):
  File "/home/atala/Personal/alx-backend-python/messaging_app/venv/lib/python3.10/site-packages/django/core/handlers/exception.py", line 55, in inner
    response = get_response(request)
  File "/home/atala/Personal/alx-backend-python/Django-Middleware-0x03/chats/middleware.py", line 48, in __call__
    raise PermissionDenied("Access is only allowed between 9 AM and 6 PM.")
django.core.exceptions.PermissionDenied: Access is only allowed between 9 AM and 6 PM.
INFO:root:2025-07-28 06:33:04.126084 - User: AnonymousUser - Path: /favicon.ico
WARNING:django.request:Forbidden (Permission denied): /favicon.ico
Traceback (most recent call last):
  File "/home/atala/Personal/alx-backend-python/messaging_app/venv/lib/python3.10/site-packages/django/core/handlers/exception.py", line 55, in inner
    response = get_response(request)
  File "/home/atala/Personal/alx-backend-python/Django-Middleware-0x03/chats/middleware.py", line 48, in __call__
    raise PermissionDenied("Access is only allowed between 9 AM and 6 PM.")
django.core.exceptions.PermissionDenied: Access is only allowed between 9 AM and 6 PM.
INFO:django.utils.autoreload:/home/atala/Personal/alx-backend-python/Django-Middleware-0x03/messaging_app/settings.py changed, reloading.
INFO:root:2025-07-28 09:34:07.648243 - User: AnonymousUser - Path: /
ERROR:django.request:Internal Server Error: /
Traceback (most recent call last):
  File "/home/atala/Personal/alx-backend-python/messaging_app/venv/lib/python3.10/site-packages/django/core/handlers/exception.py", line 55, in inner
    response = get_response(request)
TypeError: 'PermissionDenied' object is not callable
INFO:root:2025-07-28 09:34:08.122793 - User: AnonymousUser - Path: /favicon.ico
ERROR:django.request:Internal Server Error: /favicon.ico
Traceback (most recent call last):
  File "/home/atala/Personal/alx-backend-python/messaging_app/venv/lib/python3.10/site-packages/django/core/handlers/exception.py", line 55, in inner
    response = get_response(request)
TypeError: 'PermissionDenied' object is not callable
INFO:django.utils.autoreload:/home/atala/Personal/alx-backend-python/Django-Middleware-0x03/messaging_app/settings.py changed, reloading.
INFO:root:2025-07-28 09:35:29.915204 - User: AnonymousUser - Path: /
WARNING:django.request:Not Found: /
INFO:root:2025-07-28 09:35:30.155761 - User: AnonymousUser - Path: /favicon.ico
WARNING:django.request:Not Found: /favicon.ico
INFO:root:2025-07-28 09:35:55.366241 - User: AnonymousUser - Path: /
WARNING:django.request:Not Found: /
INFO:django.utils.autoreload:/home/atala/Personal/alx-backend-python/Django-Middleware-0x03/messaging_app/settings.py changed, reloading.
INFO:root:2025-07-28 06:35:58.530114 - User: AnonymousUser - Path: /
WARNING:django.request:Forbidden (Permission denied): /
Traceback (most recent call last):
  File "/home/atala/Personal/alx-backend-python/messaging_app/venv/lib/python3.10/site-packages/django/core/handlers/exception.py", line 55, in inner
    response = get_response(request)
  File "/home/atala/Personal/alx-backend-python/Django-Middleware-0x03/chats/middleware.py", line 48, in __call__
    raise PermissionDenied("Access is only allowed between 9 AM and 6 PM.")
django.core.exceptions.PermissionDenied: Access is only allowed between 9 AM and 6 PM.
INFO:django.utils.autoreload:/home/atala/Personal/alx-backend-python/Django-Middleware-0x03/messaging_app/settings.py changed, reloading.
INFO:root:2025-07-28 09:36:12.012564 - User: AnonymousUser - Path: /
WARNING:django.request:Not Found: /
INFO:root:2025-07-28 15:08:28.925653 - User: AnonymousUser - Path: /
WARNING:django.request:Not Found: /
INFO:root:2025-07-28 15:08:39.091558 - User: AnonymousUser - Path: /admin/
INFO:root:2025-07-28 15:08:39.120289 - User: AnonymousUser - Path: /admin/login/
INFO:root:2025-07-28 15:08:43.118674 - User: AnonymousUser - Path: /admin/login/
INFO:root:2025-07-28 15:09:05.589934 - User: AnonymousUser - Path: /admin/login/
INFO:root:2025-07-28 15:09:09.745628 - User: AnonymousUser - Path: /admin/login/
INFO:root:2025-07-28 15:09:11.149300 - User: atala - Path: /admin/
ERROR:django.request:Internal Server Error: /admin/
Traceback (most recent call last):
  File "/home/atala/Personal/alx-backend-python/messaging_app/venv/lib/python3.10/site-packages/django/core/handlers/exception.py", line 55, in inner
    response = get_response(request)
  File "/home/atala/Personal/alx-backend-python/messaging_app/venv/lib/python3.10/site-packages/django/core/handlers/base.py", line 197, in _get_response
    response = wrapped_callback(request, *callback_args, **callback_kwargs)
  File "/home/atala/Personal/alx-backend-python/messaging_app/venv/lib/python3.10/site-packages/django/contrib/admin/sites.py", line 265, in wrapper
    return self.admin_view(view, cacheable)(*args, **kwargs)
  File "/home/atala/Personal/alx-backend-python/messaging_app/venv/lib/python3.10/site-packages/django/utils/decorators.py", line 192, in _view_wrapper
    result = _process_exception(request, e)
  File "/home/atala/Personal/alx-backend-python/messaging_app/venv/lib/python3.10/site-packages/django/utils/decorators.py", line 190, in _view_wrapper
    response = view_func(request, *args, **kwargs)
  File "/home/atala/Personal/alx-backend-python/messaging_app/venv/lib/python3.10/site-packages/django/views/decorators/cache.py", line 80, in _view_wrapper
    response = view_func(request, *args, **kwargs)
  File "/home/atala/Personal/alx-backend-python/messaging_app/venv/lib/python3.10/site-packages/django/contrib/admin/sites.py", line 246, in inner
    return view(request, *args, **kwargs)
  File "/home/atala/Personal/alx-backend-python/messaging_app/venv/lib/python3.10/site-packages/django/contrib/admin/sites.py", line 562, in index
    app_list = self.get_app_list(request)
  File "/home/atala/Personal/alx-backend-python/messaging_app/venv/lib/python3.10/site-packages/django/contrib/admin/sites.py", line 546, in get_app_list
    app_dict = self._build_app_dict(request, app_label)
  File "/home/atala/Personal/alx-backend-python/messaging_app/venv/lib/python3.10/site-packages/django/contrib/admin/sites.py", line 488, in _build_app_dict
    has_module_perms = model_admin.has_module_permission(request)
  File "/home/atala/Personal/alx-backend-python/messaging_app/venv/lib/python3.10/site-packages/django/contrib/admin/options.py", line 641, in has_module_permission
    return request.user.has_module_perms(self.opts.app_label)
  File "/home/atala/Personal/alx-backend-python/messaging_app/venv/lib/python3.10/site-packages/django/utils/functional.py", line 253, in inner
    return func(_wrapped, *args)
AttributeError: 'CustomUser' object has no attribute 'has_module_perms'
INFO:django.utils.autoreload:/home/atala/Personal/alx-backend-python/Django-Middleware-0x03/chats/middleware.py changed, reloading.
INFO:django.utils.autoreload:/home/atala/Personal/alx-backend-python/Django-Middleware-0x03/chats/middleware.py changed, reloading.
INFO:root:2025-07-28 15:10:26.755851 - User: atala - Path: /admin/
ERROR:django.request:Internal Server Error: /admin/
Traceback (most recent call last):
  File "/home/atala/Personal/alx-backend-python/messaging_app/venv/lib/python3.10/site-packages/django/core/handlers/exception.py", line 55, in inner
    response = get_response(request)
  File "/home/atala/Personal/alx-backend-python/messaging_app/venv/lib/python3.10/site-packages/django/core/handlers/base.py", line 197, in _get_response
    response = wrapped_callback(request, *callback_args, **callback_kwargs)
  File "/home/atala/Personal/alx-backend-python/messaging_app/venv/lib/python3.10/site-packages/django/contrib/admin/sites.py", line 265, in wrapper
    return self.admin_view(view, cacheable)(*args, **kwargs)
  File "/home/atala/Personal/alx-backend-python/messaging_app/venv/lib/python3.10/site-packages/django/utils/decorators.py", line 192, in _view_wrapper
    result = _process_exception(request, e)
  File "/home/atala/Personal/alx-backend-python/messaging_app/venv/lib/python3.10/site-packages/django/utils/decorators.py", line 190, in _view_wrapper
    response = view_func(request, *args, **kwargs)
  File "/home/atala/Personal/alx-backend-python/messaging_app/venv/lib/python3.10/site-packages/django/views/decorators/cache.py", line 80, in _view_wrapper
    response = view_func(request, *args, **kwargs)
  File "/home/atala/Personal/alx-backend-python/messaging_app/venv/lib/python3.10/site-packages/django/contrib/admin/sites.py", line 246, in inner
    return view(request, *args, **kwargs)
  File "/home/atala/Personal/alx-backend-python/messaging_app/venv/lib/python3.10/site-packages/django/contrib/admin/sites.py", line 562, in index
    app_list = self.get_app_list(request)
  File "/home/atala/Personal/alx-backend-python/messaging_app/venv/lib/python3.10/site-packages/django/contrib/admin/sites.py", line 546, in get_app_list
    app_dict = self._build_app_dict(request, app_label)
  File "/home/atala/Personal/alx-backend-python/messaging_app/venv/lib/python3.10/site-packages/django/contrib/admin/sites.py", line 488, in _build_app_dict
    has_module_perms = model_admin.has_module_permission(request)
  File "/home/atala/Personal/alx-backend-python/messaging_app/venv/lib/python3.10/site-packages/django/contrib/admin/options.py", line 641, in has_module_permission
    return request.user.has_module_perms(self.opts.app_label)
  File "/home/atala/Personal/alx-backend-python/messaging_app/venv/lib/python3.10/site-packages/django/utils/functional.py", line 253, in inner
    return func(_wrapped, *args)
AttributeError: 'CustomUser' object has no attribute 'has_module_perms'
INFO:django.utils.autoreload:/home/atala/Personal/alx-backend-python/Django-Middleware-0x03/chats/middleware.py changed, reloading.
INFO:django.utils.autoreload:/home/atala/Personal/alx-backend-python/Django-Middleware-0x03/chats/middleware.py changed, reloading.
INFO:django.utils.autoreload:/home/atala/Personal/alx-backend-python/Django-Middleware-0x03/chats/middleware.py changed, reloading.
INFO:django.utils.autoreload:/home/atala/Personal/alx-backend-python/Django-Middleware-0x03/chats/middleware.py changed, reloading.
INFO:django.utils.autoreload:/home/atala/Personal/alx-backend-python/Django-Middleware-0x03/chats/middleware.py changed, reloading.
INFO:root:2025-07-28 15:14:13.703180 - User: atala - Path: /admin/
ERROR:django.request:Internal Server Error: /admin/
Traceback (most recent call last):
  File "/home/atala/Personal/alx-backend-python/messaging_app/venv/lib/python3.10/site-packages/django/core/handlers/exception.py", line 55, in inner
    response = get_response(request)
  File "/home/atala/Personal/alx-backend-python/messaging_app/venv/lib/python3.10/site-packages/django/core/handlers/base.py", line 197, in _get_response
    response = wrapped_callback(request, *callback_args, **callback_kwargs)
  File "/home/atala/Personal/alx-backend-python/messaging_app/venv/lib/python3.10/site-packages/django/contrib/admin/sites.py", line 265, in wrapper
    return self.admin_view(view, cacheable)(*args, **kwargs)
  File "/home/atala/Personal/alx-backend-python/messaging_app/venv/lib/python3.10/site-packages/django/utils/decorators.py", line 192, in _view_wrapper
    result = _process_exception(request, e)
  File "/home/atala/Personal/alx-backend-python/messaging_app/venv/lib/python3.10/site-packages/django/utils/decorators.py", line 190, in _view_wrapper
    response = view_func(request, *args, **kwargs)
  File "/home/atala/Personal/alx-backend-python/messaging_app/venv/lib/python3.10/site-packages/django/views/decorators/cache.py", line 80, in _view_wrapper
    response = view_func(request, *args, **kwargs)
  File "/home/atala/Personal/alx-backend-python/messaging_app/venv/lib/python3.10/site-packages/django/contrib/admin/sites.py", line 246, in inner
    return view(request, *args, **kwargs)
  File "/home/atala/Personal/alx-backend-python/messaging_app/venv/lib/python3.10/site-packages/django/contrib/admin/sites.py", line 562, in index
    app_list = self.get_app_list(request)
  File "/home/atala/Personal/alx-backend-python/messaging_app/venv/lib/python3.10/site-packages/django/contrib/admin/sites.py", line 546, in get_app_list
    app_dict = self._build_app_dict(request, app_label)
  File "/home/atala/Personal/alx-backend-python/messaging_app/venv/lib/python3.10/site-packages/django/contrib/admin/sites.py", line 488, in _build_app_dict
    has_module_perms = model_admin.has_module_permission(request)
  File "/home/atala/Personal/alx-backend-python/messaging_app/venv/lib/python3.10/site-packages/django/contrib/admin/options.py", line 641, in has_module_permission
    return request.user.has_module_perms(self.opts.app_label)
  File "/home/atala/Personal/alx-backend-python/messaging_app/venv/lib/python3.10/site-packages/django/utils/functional.py", line 253, in inner
    return func(_wrapped, *args)
AttributeError: 'CustomUser' object has no attribute 'has_module_perms'
INFO:root:2025-07-28 15:14:17.225328 - User: atala - Path: /admin/
ERROR:django.request:Internal Server Error: /admin/
Traceback (most recent call last):
  File "/home/atala/Personal/alx-backend-python/messaging_app/venv/lib/python3.10/site-packages/django/core/handlers/exception.py", line 55, in inner
    response = get_response(request)
  File "/home/atala/Personal/alx-backend-python/messaging_app/venv/lib/python3.10/site-packages/django/core/handlers/base.py", line 197, in _get_response
    response = wrapped_callback(request, *callback_args, **callback_kwargs)
  File "/home/atala/Personal/alx-backend-python/messaging_app/venv/lib/python3.10/site-packages/django/contrib/admin/sites.py", line 265, in wrapper
    return self.admin_view(view, cacheable)(*args, **kwargs)
  File "/home/atala/Personal/alx-backend-python/messaging_app/venv/lib/python3.10/site-packages/django/utils/decorators.py", line 192, in _view_wrapper
    result = _process_exception(request, e)
  File "/home/atala/Personal/alx-backend-python/messaging_app/venv/lib/python3.10/site-packages/django/utils/decorators.py", line 190, in _view_wrapper
    response = view_func(request, *args, **kwargs)
  File "/home/atala/Personal/alx-backend-python/messaging_app/venv/lib/python3.10/site-packages/django/views/decorators/cache.py", line 80, in _view_wrapper
    response = view_func(request, *args, **kwargs)
  File "/home/atala/Personal/alx-backend-python/messaging_app/venv/lib/python3.10/site-packages/django/contrib/admin/sites.py", line 246, in inner
    return view(request, *args, **kwargs)
  File "/home/atala/Personal/alx-backend-python/messaging_app/venv/lib/python3.10/site-packages/django/contrib/admin/sites.py", line 562, in index
    app_list = self.get_app_list(request)
  File "/home/atala/Personal/alx-backend-python/messaging_app/venv/lib/python3.10/site-packages/django/contrib/admin/sites.py", line 546, in get_app_list
    app_dict = self._build_app_dict(request, app_label)
  File "/home/atala/Personal/alx-backend-python/messaging_app/venv/lib/python3.10/site-packages/django/contrib/admin/sites.py", line 488, in _build_app_dict
    has_module_perms = model_admin.has_module_permission(request)
  File "/home/atala/Personal/alx-backend-python/messaging_app/venv/lib/python3.10/site-packages/django/contrib/admin/options.py", line 641, in has_module_permission
    return request.user.has_module_perms(self.opts.app_label)
  File "/home/atala/Personal/alx-backend-python/messaging_app/venv/lib/python3.10/site-packages/django/utils/functional.py", line 253, in inner
    return func(_wrapped, *args)
AttributeError: 'CustomUser' object has no attribute 'has_module_perms'
INFO:root:2025-07-28 15:14:18.047285 - User: atala - Path: /admin/
ERROR:django.request:Internal Server Error: /admin/
Traceback (most recent call last):
  File "/home/atala/Personal/alx-backend-python/messaging_app/venv/lib/python3.10/site-packages/django/core/handlers/exception.py", line 55, in inner
    response = get_response(request)
  File "/home/atala/Personal/alx-backend-python/messaging_app/venv/lib/python3.10/site-packages/django/core/handlers/base.py", line 197, in _get_response
    response = wrapped_callback(request, *callback_args, **callback_kwargs)
  File "/home/atala/Personal/alx-backend-python/messaging_app/venv/lib/python3.10/site-packages/django/contrib/admin/sites.py", line 265, in wrapper
    return self.admin_view(view, cacheable)(*args, **kwargs)
  File "/home/atala/Personal/alx-backend-python/messaging_app/venv/lib/python3.10/site-packages/django/utils/decorators.py", line 192, in _view_wrapper
    result = _process_exception(request, e)
  File "/home/atala/Personal/alx-backend-python/messaging_app/venv/lib/python3.10/site-packages/django/utils/decorators.py", line 190, in _view_wrapper
    response = view_func(request, *args, **kwargs)
  File "/home/atala/Personal/alx-backend-python/messaging_app/venv/lib/python3.10/site-packages/django/views/decorators/cache.py", line 80, in _view_wrapper
    response = view_func(request, *args, **kwargs)
  File "/home/atala/Personal/alx-backend-python/messaging_app/venv/lib/python3.10/site-packages/django/contrib/admin/sites.py", line 246, in inner
    return view(request, *args, **kwargs)
  File "/home/atala/Personal/alx-backend-python/messaging_app/venv/lib/python3.10/site-packages/django/contrib/admin/sites.py", line 562, in index
    app_list = self.get_app_list(request)
  File "/home/atala/Personal/alx-backend-python/messaging_app/venv/lib/python3.10/site-packages/django/contrib/admin/sites.py", line 546, in get_app_list
    app_dict = self._build_app_dict(request, app_label)
  File "/home/atala/Personal/alx-backend-python/messaging_app/venv/lib/python3.10/site-packages/django/contrib/admin/sites.py", line 488, in _build_app_dict
    has_module_perms = model_admin.has_module_permission(request)
  File "/home/atala/Personal/alx-backend-python/messaging_app/venv/lib/python3.10/site-packages/django/contrib/admin/options.py", line 641, in has_module_permission
    return request.user.has_module_perms(self.opts.app_label)
  File "/home/atala/Personal/alx-backend-python/messaging_app/venv/lib/python3.10/site-packages/django/utils/functional.py", line 253, in inner
    return func(_wrapped, *args)
AttributeError: 'CustomUser' object has no attribute 'has_module_perms'
INFO:root:2025-07-28 15:14:18.699987 - User: atala - Path: /admin/
ERROR:django.request:Internal Server Error: /admin/
Traceback (most recent call last):
  File "/home/atala/Personal/alx-backend-python/messaging_app/venv/lib/python3.10/site-packages/django/core/handlers/exception.py", line 55, in inner
    response = get_response(request)
  File "/home/atala/Personal/alx-backend-python/messaging_app/venv/lib/python3.10/site-packages/django/core/handlers/base.py", line 197, in _get_response
    response = wrapped_callback(request, *callback_args, **callback_kwargs)
  File "/home/atala/Personal/alx-backend-python/messaging_app/venv/lib/python3.10/site-packages/django/contrib/admin/sites.py", line 265, in wrapper
    return self.admin_view(view, cacheable)(*args, **kwargs)
  File "/home/atala/Personal/alx-backend-python/messaging_app/venv/lib/python3.10/site-packages/django/utils/decorators.py", line 192, in _view_wrapper
    result = _process_exception(request, e)
  File "/home/atala/Personal/alx-backend-python/messaging_app/venv/lib/python3.10/site-packages/django/utils/decorators.py", line 190, in _view_wrapper
    response = view_func(request, *args, **kwargs)
  File "/home/atala/Personal/alx-backend-python/messaging_app/venv/lib/python3.10/site-packages/django/views/decorators/cache.py", line 80, in _view_wrapper
    response = view_func(request, *args, **kwargs)
  File "/home/atala/Personal/alx-backend-python/messaging_app/venv/lib/python3.10/site-packages/django/contrib/admin/sites.py", line 246, in inner
    return view(request, *args, **kwargs)
  File "/home/atala/Personal/alx-backend-python/messaging_app/venv/lib/python3.10/site-packages/django/contrib/admin/sites.py", line 562, in index
    app_list = self.get_app_list(request)
  File "/home/atala/Personal/alx-backend-python/messaging_app/venv/lib/python3.10/site-packages/django/contrib/admin/sites.py", line 546, in get_app_list
    app_dict = self._build_app_dict(request, app_label)
  File "/home/atala/Personal/alx-backend-python/messaging_app/venv/lib/python3.10/site-packages/django/contrib/admin/sites.py", line 488, in _build_app_dict
    has_module_perms = model_admin.has_module_permission(request)
  File "/home/atala/Personal/alx-backend-python/messaging_app/venv/lib/python3.10/site-packages/django/contrib/admin/options.py", line 641, in has_module_permission
    return request.user.has_module_perms(self.opts.app_label)
  File "/home/atala/Personal/alx-backend-python/messaging_app/venv/lib/python3.10/site-packages/django/utils/functional.py", line 253, in inner
    return func(_wrapped, *args)
AttributeError: 'CustomUser' object has no attribute 'has_module_perms'
INFO:django.utils.autoreload:/home/atala/Personal/alx-backend-python/Django-Middleware-0x03/chats/middleware.py changed, reloading.
INFO:django.utils.autoreload:/home/atala/Personal/alx-backend-python/Django-Middleware-0x03/chats/middleware.py changed, reloading.
INFO:root:2025-07-28 15:14:52.908068 - User: atala - Path: /admin/
ERROR:django.request:Internal Server Error: /admin/
Traceback (most recent call last):
  File "/home/atala/Personal/alx-backend-python/messaging_app/venv/lib/python3.10/site-packages/django/core/handlers/exception.py", line 55, in inner
    response = get_response(request)
  File "/home/atala/Personal/alx-backend-python/Django-Middleware-0x03/chats/middleware.py", line 63, in __call__
    count += 1
UnboundLocalError: local variable 'count' referenced before assignment
INFO:root:2025-07-28 15:14:53.834825 - User: atala - Path: /admin/
ERROR:django.request:Internal Server Error: /admin/
Traceback (most recent call last):
  File "/home/atala/Personal/alx-backend-python/messaging_app/venv/lib/python3.10/site-packages/django/core/handlers/exception.py", line 55, in inner
    response = get_response(request)
  File "/home/atala/Personal/alx-backend-python/Django-Middleware-0x03/chats/middleware.py", line 63, in __call__
    count += 1
UnboundLocalError: local variable 'count' referenced before assignment
INFO:root:2025-07-28 15:14:58.137421 - User: atala - Path: /admin/
ERROR:django.request:Internal Server Error: /admin/
Traceback (most recent call last):
  File "/home/atala/Personal/alx-backend-python/messaging_app/venv/lib/python3.10/site-packages/django/core/handlers/exception.py", line 55, in inner
    response = get_response(request)
  File "/home/atala/Personal/alx-backend-python/Django-Middleware-0x03/chats/middleware.py", line 63, in __call__
    count += 1
UnboundLocalError: local variable 'count' referenced before assignment
INFO:django.utils.autoreload:/home/atala/Personal/alx-backend-python/Django-Middleware-0x03/chats/middleware.py changed, reloading.
INFO:django.utils.autoreload:/home/atala/Personal/alx-backend-python/Django-Middleware-0x03/chats/middleware.py changed, reloading.
INFO:root:2025-07-28 15:15:27.790061 - User: atala - Path: /admin/
ERROR:django.request:Internal Server Error: /admin/
Traceback (most recent call last):
  File "/home/atala/Personal/alx-backend-python/messaging_app/venv/lib/python3.10/site-packages/django/core/handlers/exception.py", line 55, in inner
    response = get_response(request)
  File "/home/atala/Personal/alx-backend-python/messaging_app/venv/lib/python3.10/site-packages/django/core/handlers/base.py", line 197, in _get_response
    response = wrapped_callback(request, *callback_args, **callback_kwargs)
  File "/home/atala/Personal/alx-backend-python/messaging_app/venv/lib/python3.10/site-packages/django/contrib/admin/sites.py", line 265, in wrapper
    return self.admin_view(view, cacheable)(*args, **kwargs)
  File "/home/atala/Personal/alx-backend-python/messaging_app/venv/lib/python3.10/site-packages/django/utils/decorators.py", line 192, in _view_wrapper
    result = _process_exception(request, e)
  File "/home/atala/Personal/alx-backend-python/messaging_app/venv/lib/python3.10/site-packages/django/utils/decorators.py", line 190, in _view_wrapper
    response = view_func(request, *args, **kwargs)
  File "/home/atala/Personal/alx-backend-python/messaging_app/venv/lib/python3.10/site-packages/django/views/decorators/cache.py", line 80, in _view_wrapper
    response = view_func(request, *args, **kwargs)
  File "/home/atala/Personal/alx-backend-python/messaging_app/venv/lib/python3.10/site-packages/django/contrib/admin/sites.py", line 246, in inner
    return view(request, *args, **kwargs)
  File "/home/atala/Personal/alx-backend-python/messaging_app/venv/lib/python3.10/site-packages/django/contrib/admin/sites.py", line 562, in index
    app_list = self.get_app_list(request)
  File "/home/atala/Personal/alx-backend-python/messaging_app/venv/lib/python3.10/site-packages/django/contrib/admin/sites.py", line 546, in get_app_list
    app_dict = self._build_app_dict(request, app_label)
  File "/home/atala/Personal/alx-backend-python/messaging_app/venv/lib/python3.10/site-packages/django/contrib/admin/sites.py", line 488, in _build_app_dict
    has_module_perms = model_admin.has_module_permission(request)
  File "/home/atala/Personal/alx-backend-python/messaging_app/venv/lib/python3.10/site-packages/django/contrib/admin/options.py", line 641, in has_module_permission
    return request.user.has_module_perms(self.opts.app_label)
  File "/home/atala/Personal/alx-backend-python/messaging_app/venv/lib/python3.10/site-packages/django/utils/functional.py", line 253, in inner
    return func(_wrapped, *args)
AttributeError: 'CustomUser' object has no attribute 'has_module_perms'
INFO:root:2025-07-28 15:15:29.051600 - User: atala - Path: /admin/
ERROR:django.request:Internal Server Error: /admin/
Traceback (most recent call last):
  File "/home/atala/Personal/alx-backend-python/messaging_app/venv/lib/python3.10/site-packages/django/core/handlers/exception.py", line 55, in inner
    response = get_response(request)
  File "/home/atala/Personal/alx-backend-python/messaging_app/venv/lib/python3.10/site-packages/django/core/handlers/base.py", line 197, in _get_response
    response = wrapped_callback(request, *callback_args, **callback_kwargs)
  File "/home/atala/Personal/alx-backend-python/messaging_app/venv/lib/python3.10/site-packages/django/contrib/admin/sites.py", line 265, in wrapper
    return self.admin_view(view, cacheable)(*args, **kwargs)
  File "/home/atala/Personal/alx-backend-python/messaging_app/venv/lib/python3.10/site-packages/django/utils/decorators.py", line 192, in _view_wrapper
    result = _process_exception(request, e)
  File "/home/atala/Personal/alx-backend-python/messaging_app/venv/lib/python3.10/site-packages/django/utils/decorators.py", line 190, in _view_wrapper
    response = view_func(request, *args, **kwargs)
  File "/home/atala/Personal/alx-backend-python/messaging_app/venv/lib/python3.10/site-packages/django/views/decorators/cache.py", line 80, in _view_wrapper
    response = view_func(request, *args, **kwargs)
  File "/home/atala/Personal/alx-backend-python/messaging_app/venv/lib/python3.10/site-packages/django/contrib/admin/sites.py", line 246, in inner
    return view(request, *args, **kwargs)
  File "/home/atala/Personal/alx-backend-python/messaging_app/venv/lib/python3.10/site-packages/django/contrib/admin/sites.py", line 562, in index
    app_list = self.get_app_list(request)
  File "/home/atala/Personal/alx-backend-python/messaging_app/venv/lib/python3.10/site-packages/django/contrib/admin/sites.py", line 546, in get_app_list
    app_dict = self._build_app_dict(request, app_label)
  File "/home/atala/Personal/alx-backend-python/messaging_app/venv/lib/python3.10/site-packages/django/contrib/admin/sites.py", line 488, in _build_app_dict
    has_module_perms = model_admin.has_module_permission(request)
  File "/home/atala/Personal/alx-backend-python/messaging_app/venv/lib/python3.10/site-packages/django/contrib/admin/options.py", line 641, in has_module_permission
    return request.user.has_module_perms(self.opts.app_label)
  File "/home/atala/Personal/alx-backend-python/messaging_app/venv/lib/python3.10/site-packages/django/utils/functional.py", line 253, in inner
    return func(_wrapped, *args)
AttributeError: 'CustomUser' object has no attribute 'has_module_perms'
INFO:root:2025-07-28 15:15:29.751470 - User: atala - Path: /admin/
ERROR:django.request:Internal Server Error: /admin/
Traceback (most recent call last):
  File "/home/atala/Personal/alx-backend-python/messaging_app/venv/lib/python3.10/site-packages/django/core/handlers/exception.py", line 55, in inner
    response = get_response(request)
  File "/home/atala/Personal/alx-backend-python/messaging_app/venv/lib/python3.10/site-packages/django/core/handlers/base.py", line 197, in _get_response
    response = wrapped_callback(request, *callback_args, **callback_kwargs)
  File "/home/atala/Personal/alx-backend-python/messaging_app/venv/lib/python3.10/site-packages/django/contrib/admin/sites.py", line 265, in wrapper
    return self.admin_view(view, cacheable)(*args, **kwargs)
  File "/home/atala/Personal/alx-backend-python/messaging_app/venv/lib/python3.10/site-packages/django/utils/decorators.py", line 192, in _view_wrapper
    result = _process_exception(request, e)
  File "/home/atala/Personal/alx-backend-python/messaging_app/venv/lib/python3.10/site-packages/django/utils/decorators.py", line 190, in _view_wrapper
    response = view_func(request, *args, **kwargs)
  File "/home/atala/Personal/alx-backend-python/messaging_app/venv/lib/python3.10/site-packages/django/views/decorators/cache.py", line 80, in _view_wrapper
    response = view_func(request, *args, **kwargs)
  File "/home/atala/Personal/alx-backend-python/messaging_app/venv/lib/python3.10/site-packages/django/contrib/admin/sites.py", line 246, in inner
    return view(request, *args, **kwargs)
  File "/home/atala/Personal/alx-backend-python/messaging_app/venv/lib/python3.10/site-packages/django/contrib/admin/sites.py", line 562, in index
    app_list = self.get_app_list(request)
  File "/home/atala/Personal/alx-backend-python/messaging_app/venv/lib/python3.10/site-packages/django/contrib/admin/sites.py", line 546, in get_app_list
    app_dict = self._build_app_dict(request, app_label)
  File "/home/atala/Personal/alx-backend-python/messaging_app/venv/lib/python3.10/site-packages/django/contrib/admin/sites.py", line 488, in _build_app_dict
    has_module_perms = model_admin.has_module_permission(request)
  File "/home/atala/Personal/alx-backend-python/messaging_app/venv/lib/python3.10/site-packages/django/contrib/admin/options.py", line 641, in has_module_permission
    return request.user.has_module_perms(self.opts.app_label)
  File "/home/atala/Personal/alx-backend-python/messaging_app/venv/lib/python3.10/site-packages/django/utils/functional.py", line 253, in inner
    return func(_wrapped, *args)
AttributeError: 'CustomUser' object has no attribute 'has_module_perms'
INFO:root:2025-07-28 15:15:30.167935 - User: atala - Path: /admin/
ERROR:django.request:Internal Server Error: /admin/
Traceback (most recent call last):
  File "/home/atala/Personal/alx-backend-python/messaging_app/venv/lib/python3.10/site-packages/django/core/handlers/exception.py", line 55, in inner
    response = get_response(request)
  File "/home/atala/Personal/alx-backend-python/messaging_app/venv/lib/python3.10/site-packages/django/core/handlers/base.py", line 197, in _get_response
    response = wrapped_callback(request, *callback_args, **callback_kwargs)
  File "/home/atala/Personal/alx-backend-python/messaging_app/venv/lib/python3.10/site-packages/django/contrib/admin/sites.py", line 265, in wrapper
    return self.admin_view(view, cacheable)(*args, **kwargs)
  File "/home/atala/Personal/alx-backend-python/messaging_app/venv/lib/python3.10/site-packages/django/utils/decorators.py", line 192, in _view_wrapper
    result = _process_exception(request, e)
  File "/home/atala/Personal/alx-backend-python/messaging_app/venv/lib/python3.10/site-packages/django/utils/decorators.py", line 190, in _view_wrapper
    response = view_func(request, *args, **kwargs)
  File "/home/atala/Personal/alx-backend-python/messaging_app/venv/lib/python3.10/site-packages/django/views/decorators/cache.py", line 80, in _view_wrapper
    response = view_func(request, *args, **kwargs)
  File "/home/atala/Personal/alx-backend-python/messaging_app/venv/lib/python3.10/site-packages/django/contrib/admin/sites.py", line 246, in inner
    return view(request, *args, **kwargs)
  File "/home/atala/Personal/alx-backend-python/messaging_app/venv/lib/python3.10/site-packages/django/contrib/admin/sites.py", line 562, in index
    app_list = self.get_app_list(request)
  File "/home/atala/Personal/alx-backend-python/messaging_app/venv/lib/python3.10/site-packages/django/contrib/admin/sites.py", line 546, in get_app_list
    app_dict = self._build_app_dict(request, app_label)
  File "/home/atala/Personal/alx-backend-python/messaging_app/venv/lib/python3.10/site-packages/django/contrib/admin/sites.py", line 488, in _build_app_dict
    has_module_perms = model_admin.has_module_permission(request)
  File "/home/atala/Personal/alx-backend-python/messaging_app/venv/lib/python3.10/site-packages/django/contrib/admin/options.py", line 641, in has_module_permission
    return request.user.has_module_perms(self.opts.app_label)
  File "/home/atala/Personal/alx-backend-python/messaging_app/venv/lib/python3.10/site-packages/django/utils/functional.py", line 253, in inner
    return func(_wrapped, *args)
AttributeError: 'CustomUser' object has no attribute 'has_module_perms'
INFO:root:2025-07-28 15:15:38.404763 - User: atala - Path: /admin/
ERROR:django.request:Internal Server Error: /admin/
Traceback (most recent call last):
  File "/home/atala/Personal/alx-backend-python/messaging_app/venv/lib/python3.10/site-packages/django/core/handlers/exception.py", line 55, in inner
    response = get_response(request)
  File "/home/atala/Personal/alx-backend-python/messaging_app/venv/lib/python3.10/site-packages/django/core/handlers/base.py", line 197, in _get_response
    response = wrapped_callback(request, *callback_args, **callback_kwargs)
  File "/home/atala/Personal/alx-backend-python/messaging_app/venv/lib/python3.10/site-packages/django/contrib/admin/sites.py", line 265, in wrapper
    return self.admin_view(view, cacheable)(*args, **kwargs)
  File "/home/atala/Personal/alx-backend-python/messaging_app/venv/lib/python3.10/site-packages/django/utils/decorators.py", line 192, in _view_wrapper
    result = _process_exception(request, e)
  File "/home/atala/Personal/alx-backend-python/messaging_app/venv/lib/python3.10/site-packages/django/utils/decorators.py", line 190, in _view_wrapper
    response = view_func(request, *args, **kwargs)
  File "/home/atala/Personal/alx-backend-python/messaging_app/venv/lib/python3.10/site-packages/django/views/decorators/cache.py", line 80, in _view_wrapper
    response = view_func(request, *args, **kwargs)
  File "/home/atala/Personal/alx-backend-python/messaging_app/venv/lib/python3.10/site-packages/django/contrib/admin/sites.py", line 246, in inner
    return view(request, *args, **kwargs)
  File "/home/atala/Personal/alx-backend-python/messaging_app/venv/lib/python3.10/site-packages/django/contrib/admin/sites.py", line 562, in index
    app_list = self.get_app_list(request)
  File "/home/atala/Personal/alx-backend-python/messaging_app/venv/lib/python3.10/site-packages/django/contrib/admin/sites.py", line 546, in get_app_list
    app_dict = self._build_app_dict(request, app_label)
  File "/home/atala/Personal/alx-backend-python/messaging_app/venv/lib/python3.10/site-packages/django/contrib/admin/sites.py", line 488, in _build_app_dict
    has_module_perms = model_admin.has_module_permission(request)
  File "/home/atala/Personal/alx-backend-python/messaging_app/venv/lib/python3.10/site-packages/django/contrib/admin/options.py", line 641, in has_module_permission
    return request.user.has_module_perms(self.opts.app_label)
  File "/home/atala/Personal/alx-backend-python/messaging_app/venv/lib/python3.10/site-packages/django/utils/functional.py", line 253, in inner
    return func(_wrapped, *args)
AttributeError: 'CustomUser' object has no attribute 'has_module_perms'
INFO:django.utils.autoreload:/home/atala/Personal/alx-backend-python/Django-Middleware-0x03/chats/middleware.py changed, reloading.
INFO:django.utils.autoreload:/home/atala/Personal/alx-backend-python/Django-Middleware-0x03/messaging_app/settings.py changed, reloading.
